Workbook
Name OLE_LINK1: 合并口径财务报表!#REF!
Name OLE_LINK2: '报告（自动生成）'!#REF!
Name OLE_LINK5: '报告（自动生成）'!#REF!

Sheet 材料汇总
B2: 后续页项目所须填写的所有数据均为合并层面数据。 | C2: 除了员工薪酬表单位：元，其他表单位：万元
B4: 贵公司近两年一期合并报表、母子单体报表（纸质敲公章件）；已提供
B5: 贵公司母子公司最新企业征信报告（纸质敲公章件）；已提供
B6: 贵公司母子公司最近一期末月的所有银行活期账户、定存账户、理财户对账单（纸质敲公章件）； | D6: 已提供
B7: 贵公司近两年一期合并、单体审计报告；已提供
B8: 贵公司近两年一期合并报表的合并抵消分录、合并过程底稿；已提供
B9: 贵公司母子公司近两年一期电子明细账（序时账及科目余额表末级）；已提供
B10: 贵公司近两年一期合并层面按客户列式或合同列式的收入成本台账；不适用
B11: 贵公司近两年一期各主要公司六大往来（应收应付、其他应收应付、预收预付）按客户或供应商的余额表，能看到各客户和供应商期初、期末以及本年发生借贷方额； | I11: 已提供
B12: 贵公司近两年一期利润分配文件；不适用
B13: 各公司最新固定资产卡片账；已提供
B14: 贵公司母子公司近两年一期纳税申报表。包括合并范围内所有公司的所得税纳税申报表及增值税纳税申报表。 | D14: 已提供
B15: 贵公司合同清单，包括合同主要条款。（并且准备好原始文件以备核数人员在现场查验） | C15: 已提供
B16: 贵公司未来期间大额资金支出计划项目明细及对应预算（包括如土地厂房购置、预计大额投入的研发项目等，但不包括正常生产资料采购或人员招聘） | G16: 不涉及
B17: 请仔细填写后续相关报表附注内容。已提供
B19: 上述文件请在进场前以电子版形式准备好并发出，有任何疑问请联系本次财务尽调负责人：

Sheet 内部关联方基本信息
B2: 母、子公司名 | C2: 实际业务概括 | D2: 持股比例 | E2: 纳入合并范围时间 | F2: 是否为同一控制下合并 | G2: 对第三方收入
G3: 2020年1-6月 | H3: 2019年 | I3: 2018年
B4: 北京眼神科技有限公司 | C4: 集团的研发中心、生产中心 | G4: 167.66219 | H4: 701.69049 | I4: 605.20178
B5: 北京天诚智能科技有限公司 | C5: 原集团产品的专业销售公司，目前已无实际经营 | D5: 1 | E5: 2018年 | F5: 是 | G5: 28.763817 | H5: 166.87686 | I5: 195.10593
B6: 山东眼神智能科技有限公司 | C6: 集团智慧校园领域的专项研发及销售公司 | D6: 0.85 | E6: 2018年 | F6: 是 | G6: 0 | H6: 75.840436 | I6: 5.001747
B7: 深圳爱酷智能科技有限公司 | C7: 原集团生产中心，业务于2019年11月转移至母公司，目前业务主要为虹膜锁的研发与生产 | D7: 1 | E7: 2018年 | F7: 是 | G7: 0.829909 | H7: 296.08434 | I7: 450.56858
B8: 深圳眼神智能科技有限公司 | C8: 集团社区反恐领域的专项研发及销售公司 | D8: 1 | E8: 2018年 | F8: 是 | G8: 2.725281 | H8: 21.02636 | I8: 172.59457
B9: 北京探日咨询管理有限公司 | C9: 无实际经营 | D9: 1 | E9: 2018年 | F9: 是 | G9: 0 | H9: 0 | I9: 0
B10: 北京眼神智能科技有限公司 | C10: 金融行业的专业销售公司 | D10: 1 | E10: 2018年 | F10: 是 | G10: 5028.5798 | H10: 15616.778 | I10: 8857.3877
B11: 北京眼神人工智能技术研究院 | C11: 无实际经营 | D11: 0.49 | E11: 2018年 | F11: 是
B12: 上海眼神信息服务有限公司 | C12: 区域销售公司 | D12: 1 | E12: 2018年 | F12: 是
F13: 合计 | G13: =SUM(G4:G12) -> 5228.561 | H13: =SUM(H4:H12) -> 16878.297 | I13: =SUM(I4:I12) -> 10285.86

Sheet 关联方交易
B2: 非合并范围的关联方交易发生额（包括业务性质、非业务性质）
B3: 项目 | C3: 2020年1-6月 | E3: 2019年 | G3: 2018年
B4: 关联方名称 | C4: 交易内容 | D4: 当年累计交易额 | E4: 交易内容 | F4: 当年累计交易额 | G4: 交易内容 | H4: 当年累计交易额
D5: 不含税 | F5: 不含税 | H5: 不含税
B6: 张亚华 | E6: 房租 | F6: 15.25 | G6: 房租 | H6: 15.25
B7: 杨春林 | E7: 房租 | F7: 40.75 | G7: 房租 | H7: 40.75
B16: 非合并范围的关联方交易期末余额
B17: 项目 | C17: =C3 -> 2020年1-6月 | E17: =E3 -> 2019年 | G17: =G3 -> 2018年
B18: 关联方名称 | C18: 往来科目 | D18: 期末金额 | E18: 往来科目 | F18: 期末金额 | G18: 往来科目 | H18: 期末金额
B19: 北京探辰管理咨询合伙企业（有限合伙） | C19: 其他应收款 | D19: 4.08 | E19: 其他应收款 | F19: 4.08 | G19: 其他应收款 | H19: 4.08
B20: 北京探星管理咨询合伙企业（有限合伙） | C20: 其他应收款 | D20: 4.08 | E20: 其他应收款 | F20: 4.08 | G20: 其他应收款 | H20: 4.08
B21: 北京探月管理咨询合伙企业（有限合伙） | C21: 其他应收款 | D21: 4.05 | E21: 其他应收款 | F21: 4.05 | G21: 其他应收款 | H21: 4.05
B22: 深圳探日咨询管理有限公司 | C22: 其他应收款 | D22: 1.3774 | E22: 其他应收款 | F22: 1.3774 | G22: 其他应收款 | H22: 0
B23: 潘金华 | C23: 其他应收款 | D23: 17.685171 | E23: 其他应收款 | F23: 10.454293 | G23: 其他应收款 | H23: 77.12055
B24: 王丙光 | C24: 其他应收款 | D24: 0 | E24: 其他应收款 | F24: 0 | G24: 其他应收款 | H24: 110
B25: 王厚金 | C25: 其他应收款 | D25: 45.452978 | E25: 其他应收款 | F25: 15.452978 | G25: 其他应收款 | H25: 17.1
B26: 杨春林 | C26: 其他应收款 | D26: 3.25 | E26: 其他应收款 | F26: 15.86985 | G26: 其他应收款 | H26: 95.122014
B27: 张亚华 | C27: 其他应收款 | D27: 20 | E27: 其他应收款 | F27: 20 | G27: 其他应收款 | H27: 20
B28: 周军 | C28: 其他应收款 | D28: 0.729076 | E28: 其他应收款 | F28: 1.217624 | G28: 其他应收款 | H28: 1.338084
B29: 周长金 | C29: 其他应收款 | D29: 26.37 | E29: 其他应收款 | F29: 26.37 | G29: 其他应收款 | H29: 24.35747
B30: 陈瑞丹 | C30: 其他应付款 | D30: 2.8705 | E30: 其他应付款 | F30: 0 | G30: 其他应付款 | H30: 2.8705
... B36: 周长金 | C36: 其他应付款 | D36: 0.036 | E36: 其他应付款 | F36: 0.036 | G36: 其他应付款 | H36: 0.036

Sheet 实收资本
B1: 截至尽调日
B2: 股东名称 | C2: 认缴资本 | D2: 实缴资本 | F2: 出资形式 | G2: 比例
D3: 实收资本 | E3: 资本公积
B4: 深圳探日咨询管理有限公司 | C4: 3373.95 | D4: 3373.95 | E4: 1260 | F4: 货币资金 | G4: 0.6468
B5: 北京探月管理咨询合伙企业（有限合伙） | C5: 221.5 | D5: 221.5 | E5: 0 | F5: 货币资金 | G5: 0.0443
B6: 北京探星管理咨询合伙企业（有限合伙） | C6: 620.1 | D6: 620.1 | E6: 0 | F6: 货币资金 | G6: 0.124
B7: 北京探辰管理咨询合伙企业（有限合伙） | C7: 354.45 | D7: 354.45 | E7: 0 | F7: 货币资金 | G7: 0.0709
B8: 先锋国盛启明星1号私募股权投资基金 | C8: 570 | D8: 570 | E8: 2900 | F8: 货币资金 | G8: 0.114
B9: 其他-股份支付 | C9: 0 | D9: 0 | E9: 2199.7669
B10: 山东眼神股东潘穷穷 | C10: 0 | D10: 0 | E10: 805.00368
B11: 合计 | C11: =SUM(C4:C10) -> 5140 | D11: =SUM(D4:D10) -> 5140 | E11: =SUM(E4:E10) -> 7164.7706

Sheet 盈利预测
E1: 人员预测
B2: 项目 | C2: 2020E | D2: 请逐项说明预测依据 | E2: 2020E
B3: 一、营业收入 | C3: 25000 | D3: 根据今年战略目标
B4: 减：营业成本 | C4: 9500 | D4: 根据公司历史毛利率
B5: 营业税金及附加 | C5: 60 | D5: 根据税负
B6: 销售费用 | C6: 4500 | D6: 结合历史数据推算，上市后品牌效应会带来销售费用率降低，结合销售人员配备：20E:60人及其和人相关的费用 | E6: =60*30 -> 1800
B7: 管理费用 | C7: 2895 | D7: 结合历史数据推算，上市后引进高端人才，20E:50人及其和人相关的费用 | E7: =7*150+44*20 -> 1930
B8: 研发费用 | C8: 4500 | D8: 上市后公司加大研发投入：20E:100多人及其和人相关的费用，保持研发投入不低于收入的15% | E8: =100*30 -> 3000
B9: 财务费用 | C9: 195.75 | D9: 上市后不再进行短期贷款
B10: 资产减值损失
B11: 加：其他收益 | C11: 1455 | D11: 增值税即征即退收入
B12: 投资收益
B13: 二、营业利润 | C13: 4804.25
B14: 加：营业外收入 | C14: 500 | D14: 获取政府补贴
B15: 减：营业外支出
B16: 三、利润总额 | C16: 5304.25
B17: 减：所得税费用 | C17: 323.1375
B18: 四、净利润 | C18: 4981.1125
B19: 毛利率 | C19: 0.62
B20: 销售费用率 | C20: 0.18
B21: 管理费用率 | C21: 0.1158
B22: 营业利润率 | C22: 0.19217
B23: 净利率 | C23: 0.1992445
B26: 上表中收入及成本明细请进一步拆分
B27: 业务类型 | C27: 收入 | D27: 成本 | E27: 数量（如适用）

Sheet 合并口径财务报表
B2: 项目 | C2: 2020年1-6月 | D2: 2019年 | E2: 2018年
B3: 营业收入 | C3: 52285610 | D3: 1.6878297e+08 | E3: 1.028586e+08
B4: 减：营业成本 | C4: 18704844 | D4: 62259075 | E4: 48973869
B5: 税金及附加 | C5: 320765.72 | D5: 1733639.1 | E5: 1000475.5
B6: 销售费用 | C6: 10686228 | D6: 27058955 | E6: 26546432
B7: 管理费用 | C7: 10758745 | D7: 25466452 | E7: 39143770
B8: 研发费用 | C8: 13073869 | D8: 19253676 | E8: 38476829
B9: 财务费用 | C9: 1018185.4 | D9: 4025482.8 | E9: 1535045.2
B10: 其中：利息费用
B11: 利息收入
B12: 资产减值损失 | C12: -51121.94 | D12: -260037.34 | E12: 1028571.3
B13: 加：其他收益 | C13: 3222177.2 | D13: 4412148.3 | E13: 4332560.4
B14: 投资收益（损失以“-”号填列） | C14: -162640.31
B15: 其中：对联营企业和合营企业的投资收益
B16: 公允价值变动收益（损失以“-”号填列）
B17: 资产处置收益（损失以“-”号填列） | D17: 10976.08 | E17: 2182.94
B18: 营业利润 | C18: =C3-C4-C5-C6-C7-C8-C9-C12+C17+C14+C13+C16 -> 833632.35 | D18: =D3-D4-D5-D6-D7-D8-D9-D12+D17+D14+D13+D16 -> 33668852 | E18: =E3-E4-E5-E6-E7-E8-E9-E12+E17+E14+E13+E16 -> -49511645
B19: 加：营业外收入 | C19: 263707.32 | D19: 257893.72 | E19: 119442.23
B20: 减：营业外支出 | C20: 5675.97 | D20: 8941.92 | E20: 443773.86
B21: 利润总额 | C21: =C18+C19-C20 -> 1091663.7 | D21: =D18+D19-D20 -> 33917804 | E21: =E18+E19-E20 -> -49835976
B22: 减：所得税费用 | C22: -92672.81 | D22: 4627049.2 | E22: -7689264.8
B23: 净利润 | C23: =C21-C22 -> 1184336.5 | D23: =D21-D22 -> 29290755 | E23: =E21-E22 -> -42146712
B24: 归属少数股东的净利润 | C24: -292149.68 | D24: -5233.47 | E24: -875691.55
B25: 归属于母公司的净利润 | C25: =C23-C24 -> 1476486.2 | D25: =D23-D24 -> 29295988 | E25: =E23-E24 -> -41271020
B28: 资产 | C28: 2020年6月30日 | D28: 2019年12月31日 | E28: 2018年12月31日
B29: 流动资产：
B30: 货币资金 | C30: 6235100.8 | D30: 7066692.7 | E30: 5555950.7
B31: 以公允价值计量且其变动计入当期损益的金融资产 | C31: 100000
B32: 衍生金融资产
B33: 应收票据 | C33: 2753608.6 | D33: 3678946.6 | E33: 4278736.8
B34: 应收账款 | C34: 62606575 | D34: 65784661 | E34: 28800007
B35: 预付账款 | C35: 4285208.6 | D35: 2758644.7 | E35: 5721705.2
B36: 其他应收款 | C36: 10530187 | D36: 6753864.4 | E36: 7541581.5
B37: 存货 | C37: 21156647 | D37: 20023878 | E37: 20642195
B38: 持有待售资产
B39: 一年内到期的非流动资产
B40: 其他流动资产 | C40: 260035.22 | D40: 1389490 | E40: 260756.82
B41: 非流动资产：
B42: 可供出售金融资产
B43: 持有至到期投资
...

Sheet 报告（自动生成）
B2: 项目 | C2: =合并口径财务报表!$C$2 -> 2020年1-6月 | D2: =合并口径财务报表!$D$2 -> 2019年 | E2: =合并口径财务报表!$E$2 -> 2018年
B3: =合并口径财务报表!B3 -> 营业收入 | C3: =合并口径财务报表!C3/10000 -> 5228.561 | D3: =合并口径财务报表!D3/10000 -> 16878.297 | E3: =合并口径财务报表!E3/10000 -> 10285.86
B4: =合并口径财务报表!B4 -> 减：营业成本 | C4: =合并口径财务报表!C4/10000 -> 1870.4844 | D4: =合并口径财务报表!D4/10000 -> 6225.9075 | E4: =合并口径财务报表!E4/10000 -> 4897.3869
B5: =合并口径财务报表!B5 -> 税金及附加 | C5: =合并口径财务报表!C5/10000 -> 32.076572 | D5: =合并口径财务报表!D5/10000 -> 173.36391 | E5: =合并口径财务报表!E5/10000 -> 100.04755
B6: =合并口径财务报表!B6 -> 销售费用 | C6: =合并口径财务报表!C6/10000 -> 1068.6228 | D6: =合并口径财务报表!D6/10000 -> 2705.8955 | E6: =合并口径财务报表!E6/10000 -> 2654.6432
B7: =合并口径财务报表!B7 -> 管理费用 | C7: =合并口径财务报表!C7/10000 -> 1075.8745 | D7: =合并口径财务报表!D7/10000 -> 2546.6452 | E7: =合并口径财务报表!E7/10000 -> 3914.377
B8: =合并口径财务报表!B8 -> 研发费用 | C8: =合并口径财务报表!C8/10000 -> 1307.3869 | D8: =合并口径财务报表!D8/10000 -> 1925.3676 | E8: =合并口径财务报表!E8/10000 -> 3847.6829
B9: =合并口径财务报表!B9 -> 财务费用 | C9: =合并口径财务报表!C9/10000 -> 101.81854 | D9: =合并口径财务报表!D9/10000 -> 402.54828 | E9: =合并口径财务报表!E9/10000 -> 153.50452
B10: =合并口径财务报表!B10 -> 其中：利息费用 | C10: =合并口径财务报表!C10/10000 -> 0 | D10: =合并口径财务报表!D10/10000 -> 0 | E10: =合并口径财务报表!E10/10000 -> 0
B11: =合并口径财务报表!B11 -> 利息收入 | C11: =合并口径财务报表!C11/10000 -> 0 | D11: =合并口径财务报表!D11/10000 -> 0 | E11: =合并口径财务报表!E11/10000 -> 0
B12: =合并口径财务报表!B12 -> 资产减值损失 | C12: =合并口径财务报表!C12/10000 -> -5.112194 | D12: =合并口径财务报表!D12/10000 -> -26.003734 | E12: =合并口径财务报表!E12/10000 -> 102.85713
B13: =合并口径财务报表!B13 -> 加：其他收益 | C13: =合并口径财务报表!C13/10000 -> 322.21772 | D13: =合并口径财务报表!D13/10000 -> 441.21483 | E13: =合并口径财务报表!E13/10000 -> 433.25604
B14: =合并口径财务报表!B14 -> 投资收益（损失以“-”号填列） | C14: =合并口径财务报表!C14/10000 -> -16.264031 | D14: =合并口径财务报表!D14/10000 -> 0 | E14: =合并口径财务报表!E14/10000 -> 0
... B17: =合并口径财务报表!B17 -> 资产处置收益（损失以“-”号填列） | C17: =合并口径财务报表!C17/10000 -> 0 | D17: =合并口径财务报表!D17/10000 -> 1.097608 | E17: =合并口径财务报表!E17/10000 -> 0.218294
B18: =合并口径财务报表!B18 -> 营业利润 | C18: =C3-C4-C5-C6-C7-C8-C9-C12+C13+C14+C15+C16+C17 -> 83.363235 | D18: =D3-D4-D5-D6-D7-D8-D9-D12+D13+D14+D15+D16+D17 -> 3366.8852 | E18: =E3-E4-E5-E6-E7-E8-E9-E12+E13+E14+E15+E16+E17 -> -4951.1645
B19: =合并口径财务报表!B19 -> 加：营业外收入 | C19: =合并口径财务报表!C19/10000 -> 26.370732 | D19: =合并口径财务报表!D19/10000 -> 25.789372 | E19: =合并口径财务报表!E19/10000 -> 11.944223
B20: =合并口径财务报表!B20 -> 减：营业外支出 | C20: =合并口径财务报表!C20/10000 -> 0.567597 | D20: =合并口径财务报表!D20/10000 -> 0.894192 | E20: =合并口径财务报表!E20/10000 -> 44.377386
B21: =合并口径财务报表!B21 -> 利润总额 | C21: =C18-C20+C19 -> 109.16637 | D21: =D18-D20+D19 -> 3391.7804 | E21: =E18-E20+E19 -> -4983.5976
B22: =合并口径财务报表!B22 -> 减：所得税费用 | C22: =合并口径财务报表!C22/10000 -> -9.267281 | D22: =合并口径财务报表!D22/10000 -> 462.70492 | E22: =合并口径财务报表!E22/10000 -> -768.92648
B23: =合并口径财务报表!B23 -> 净利润 | C23: =C21-C22 -> 118.43365 | D23: =D21-D22 -> 2929.0755 | E23: =E21-E22 -> -4214.6712
B24: =合并口径财务报表!B24 -> 归属少数股东的净利润 | C24: =合并口径财务报表!C24/10000 -> -29.214968 | D24: =合并口径财务报表!D24/10000 -> -0.523347 | E24: =合并口径财务报表!E24/10000 -> -87.569155
B25: =合并口径财务报表!B25 -> 归属于母公司的净利润 | C25: =C23-C24 -> 147.64862 | D25: =D23-D24 -> 2929.5988 | E25: =E23-E24 -> -4127.102
C26: =C5/C3 -> 0.0061348758 | D26: =D5/D3 -> 0.01027141 | E26: =E5/E3 -> 0.0097267069
C27: =C22/C21 -> -0.084891354 | D27: =D22/D21 -> 0.13641948 | E27: =E22/E21 -> 0.15429144
B29: 项 目 | C29: =合并口径财务报表!$C$2 -> 2020年1-6月 | D29: =合并口径财务报表!$D$2 -> 2019年 | E29: =合并口径财务报表!$E$2 -> 2018年
B30: 毛利率 | C30: =1-C4/C3 -> 0.64225637 | D30: =1-D4/D3 -> 0.6311294 | E30: =1-E4/E3 -> 0.52387193
B31: 营业利润率 | C31: =C18/C3 -> 0.01594382 | D31: =D18/D3 -> 0.19948015 | E31: =E18/E3 -> -0.48135638
B32: 净利润率 | C32: =C23/C3 -> 0.02265129 | D32: =D23/D3 -> 0.17354094 | E32: =E23/E3 -> -0.40975388
B33: 年化净资产收益率 | C33: =C23/C115 -> 0.048764282 | D33: =D23/D115 -> 3.216896 | E33: =E23/E115 -> 2.0879728
B35: 项 目 | C35: =合并口径财务报表!$C$2 -> 2020年1-6月 | D35: =合并口径财务报表!$D$2 -> 2019年 | E35: =合并口径财务报表!$E$2 -> 2018年
B36: 销售费用月平均值 | C36: =C6/6 -> 178.10379 | D36: =D6/12 -> 225.49129 | E36: =E6/12 -> 221.22027
B37: 销售费用/收入 | C37: =C6/C3 -> 0.20438181 | D37: =D6/D3 -> 0.16031804 | E37: =E6/E3 -> 0.25808665
B39: 项 目 | C39: =合并口径财务报表!$C$2 -> 2020年1-6月 | D39: =合并口径财务报表!$D$2 -> 2019年 | E39: =合并口径财务报表!$E$2 -> 2018年
B40: 管理费用月平均值 | C40: =C7/6 -> 179.31242 | D40: =D7/12 -> 212.22043 | E40: =E7/12 -> 326.19808
B41: 管理费用/收入 | C41: =C7/C3 -> 0.20576876 | D41: =D7/D3 -> 0.15088283 | E41: =E7/E3 -> 0.38055903
B43: 项 目 | C43: =合并口径财务报表!$C$2 -> 2020年1-6月 | D43: =合并口径财务报表!$D$2 -> 2019年 | E43: =合并口径财务报表!$E$2 -> 2018年
B44: 研发费用月平均值 | C44: =C8/6 -> 217.89781 | D44: =D8/6 -> 320.89459 | E44: =E8/6 -> 641.28048
B45: 研发费用/收入 | C45: =C8/C3 -> 0.25004717 | D45: =D8/D3 -> 0.11407357 | E45: =E8/E3 -> 0.37407497
B47: 项目 | C47: =合并口径财务报表!$C$2 -> 2020年1-6月 | D47: =合并口径财务报表!$D$2 -> 2019年 | E47: =合并口径财务报表!$E$2 -> 2018年
B48: 四费占收入比 | C48: =(C6+C7+C8+C9)/C3 -> 0.67967127 | D48: =(D6+D7+D8+D9)/D3 -> 0.44912449 | E48: =(E6+E7+E8+E9)/E3 -> 1.0276445
...

Sheet 收入、毛利率构成表
B1: 营业收入构成表（按产品分）
B2: 收入类型 | C2: ='报告（自动生成）'!C2 -> 2020年1-6月 | G2: =合并口径财务报表!D2 -> 2019年 | K2: =合并口径财务报表!E2 -> 2018年
C3: 销售额 | D3: 成本 | E3: 毛利率 | F3: 数量（如适用） | G3: 销售额 | H3: 成本 | I3: 毛利率 | J3: 数量（如适用） | K3: 销售额 | L3: 成本 | M3: 毛利率 | N3: 数量（如适用）
B4: 指纹类产品 | C4: 2564.6761 | D4: 995.0572 | E4: 0.61201448 | F4: 不适用 | G4: 7901.7493 | H4: 2794.0067 | I4: 0.64640656 | J4: 不适用 | K4: 5788.5137 | L4: 3120.4633 | M4: 0.46092149 | N4: 不适用
B5: 软件及运维服务类 | C5: 1121.4309 | D5: 200.15067 | E5: 0.82152207 | G5: 1177.9267 | H5: 77.106637 | I5: 0.93454038 | K5: 2050.1936 | L5: 525.31678 | M5: 0.74377211
B6: 人脸类产品 | C6: 1119.0859 | D6: 471.16503 | E6: 0.57897331 | G6: 4144.344 | H6: 1812.3138 | I6: 0.56270188 | K6: 1594.2103 | L6: 788.73528 | M6: 0.50525017
B7: 虹膜类产品 | C7: 130.80101 | D7: 73.776103 | E7: 0.43596689 | G7: 2506.6214 | H7: 976.42508 | I7: 0.61046168 | K7: 127.27891 | L7: 28.807063 | M7: 0.77366979
B8: 集成类产品 | C8: 195.54516 | D8: 96.466698 | E8: 0.50667816 | G8: 770.93207 | H8: 451.14588 | I8: 0.41480463 | K8: 116.93575 | L8: 21.696222 | M8: 0.81446032
B9: 指静脉类产品 | C9: 58.004424 | D9: 10.173365 | E9: 0.82461054 | G9: 10.947992 | H9: 1.9954096 | I9: 0.81773739 | K9: 0.302564 | L9: 0.051757879 | M9: 0.82893577
B10: 其他 | C10: 39.017488 | D10: 23.692058 | E10: 0.39278361 | G10: 365.77675 | H10: 112.92085 | I10: 0.69128478 | K10: 608.42554 | L10: 412.32142 | M10: 0.32231408
B11: 合计 | C11: =SUM(C4:C10) -> 5228.561 | D11: =SUM(D4:D10) -> 1870.4811 | E11: 0.64225699 | G11: =SUM(G4:G10) -> 16878.298 | H11: =SUM(H4:H10) -> 6225.9144 | I11: 0.63112902 | K11: =SUM(K4:K10) -> 10285.86 | L11: =SUM(L4:L10) -> 4897.3918 | M11: 0.52387144
B13: 营业收入构成表（按月份分）
B14: 月份 | C14: =C2 -> 2020年1-6月 | G14: =G2 -> 2019年 | K14: =K2 -> 2018年
C15: 销售额 | D15: 成本 | E15: 毛利率 | F15: 数量（如适用） | G15: 销售额 | H15: 成本 | I15: 毛利率 | J15: 数量（如适用） | K15: 销售额 | L15: 成本 | M15: 毛利率 | N15: 数量（如适用）
B16: 1月 | C16: 647.39157 | D16: 不适用 | E16: 不适用 | F16: 不适用 | G16: 1495.4596 | H16: 不适用 | I16: 不适用 | J16: 不适用 | K16: 642.04119 | L16: 不适用 | M16: 不适用 | N16: 不适用
B17: 2月 | C17: 561.56549 | G17: 248.20362 | K17: 178.98774
B18: 3月 | C18: 1136.1081 | G18: 1366.9842 | K18: 548.2004
B19: 4月 | C19: 897.48339 | G19: 1022.6654 | K19: 615.39442
B20: 5月 | C20: 1002.3881 | G20: 860.5792 | K20: 588.18594
B21: 6月 | C21: 983.62436 | G21: 897.43086 | K21: 618.12381
B22: 7月 | G22: 1243.8008 | K22: 714.93168
B23: 8月 | G23: 1372.5482 | K23: 1312.0893
B24: 9月 | G24: 1514.9111 | K24: 814.20021
B25: 10月 | G25: 1215.5069 | K25: 778.75015
B26: 11月 | G26: 2911.4398 | K26: 688.55993
B27: 12月 | G27: 2728.7674 | K27: 2786.3956
B28: 合计 | C28: =SUM(C16:C27) -> 5228.561 | D28: =SUM(D16:D27) -> 0 | G28: =SUM(G16:G27) -> 16878.297 | H28: =SUM(H16:H27) -> 0 | K28: =SUM(K16:K27) -> 10285.86 | L28: =SUM(L16:L27) -> 0
K29: =K11-K28 -> 0
B31: 营业收入构成表（按地区分）-不适用
B32: 收入类型 | C32: =C2 -> 2020年1-6月 | G32: =G2 -> 2019年 | K32: =K2 -> 2018年
B33: 地区 | C33: 销售额 | D33: 成本 | E33: 毛利率 | F33: 数量（如适用） | G33: 销售额 | H33: 成本 | I33: 毛利率 | J33: 数量（如适用） | K33: 销售额 | L33: 成本 | M33: 毛利率 | N33: 数量（如适用）
B41: 合计

Sheet 成本构成表
B2: 项目 | C2: ='收入、毛利率构成表'!C2 -> 2020年1-6月 | E2: ='收入、毛利率构成表'!G2 -> 2019年 | G2: ='收入、毛利率构成表'!K2 -> 2018年
C3: 金额 | D3: 比例 | E3: 金额 | F3: 比例 | G3: 金额 | H3: 比例
B4: 硬件产品成本 | C4: 1514.2946 | D4: 0.80957352 | E4: 4465.7656 | F4: 0.7172875 | G4: 4479.7632 | H4: 0.9147252
B5: 软件产品成本 | C5: 224.50532 | D5: 0.12002523 | E5: 1754.9527 | F5: 0.28187903 | G5: 383.20258 | H5: 0.078246337
B6: 技术服务成本 | C6: 110.37736 | D6: 0.059010038 | E6: 4.046006 | F6: 0.00064986607 | G6: 34.421083 | H6: 0.007028459
B7: 运维成本 | C7: 21.307093 | D7: 0.011391217 | E7: 0.802199 | F7: 0.00012884853 | G7: 0 | H7: 0
B8: 其他 | D8: 0 | E8: 0.34092 | F8: 5.4758283e-05 | G8: 0 | H8: 0
B12: 合计 | C12: =SUM(C4:C11) -> 1870.4844 | D12: =SUM(D4:D11) -> 1 | E12: =SUM(E4:E11) -> 6225.9075 | F12: =SUM(F4:F11) -> 1 | G12: =SUM(G4:G11) -> 4897.3869 | H12: =SUM(H4:H11) -> 1

Sheet 前10大客户、供应商
B1: 前10名客户营业额情况表
B2: 序号 | C2: ='收入、毛利率构成表'!C2 -> 2020年1-6月 | H2: ='收入、毛利率构成表'!G2 -> 2019年 | M2: ='收入、毛利率构成表'!K2 -> 2018年
C3: 客户名称 | D3: 收入 | E3: 成本 | F3: 收入类型 | G3: 是否关联 | H3: 客户名称 | I3: 收入 | J3: 成本 | K3: 收入类型 | L3: 是否关联 | M3: 客户名称 | N3: 收入 | O3: 成本 | P3: 收入类型 | Q3: 是否关联
B4: 1 | C4: 福建升腾资讯有限公司 | D4: 595.39528 | F4: 指纹、人脸产品 | G4: 无 | H4: 湖南长城信息金融设备有限责任公司 | I4: 1626.1066 | K4: 指纹、人脸和虹膜产品 | L4: 无 | M4: 福建升腾资讯有限公司 | N4: 1232.5452 | P4: 指纹、人脸产品 | Q4: 无
B5: 2 | C5: 江苏国光信息产业股份有限公司 | D5: 473.07505 | F5: 指纹、人脸产品 | G5: 无 | H5: 深圳南天东华科技有限公司 | I5: 1452.0773 | K5: 指纹、人脸产品 | L5: 无 | M5: 贵州省安顺市公安局西秀分局 | N5: 1160.9649 | P5: 人脸产品、软件类产品 | Q5: 无
B6: 3 | C6: 交通银行股份有限公司 | D6: 379.80047 | F6: 指纹、人脸产品、软件类产品 | G6: 无 | H6: 福建升腾资讯有限公司 | I6: 1411.7835 | K6: 指纹、人脸产品 | L6: 无 | M6: 江苏国光信息产业股份有限公司 | N6: 744.62147 | P6: 指纹、人脸产品 | Q6: 无
B7: 4 | C7: 浙江省公众信息产业有限公司 | D7: 318.81329 | F7: 人脸产品、集成产品 | G7: 无 | H7: 江苏国光信息产业股份有限公司 | I7: 983.80254 | K7: 指纹、人脸产品 | L7: 无 | M7: 珠海汇金科技股份有限公司 | N7: 607.84612 | P7: 指纹产品 | Q7: 无
B8: 5 | C8: 湖南长城信息金融设备有限责任公司 | D8: 283.40543 | F8: 指纹、人脸和虹膜产品 | G8: 无 | H8: 山东大学 | I8: 683.2301 | K8: 人脸产品、集成产品、软件类产品 | L8: 无 | M8: 河北雄安睿谋商贸有限公司 | N8: 598.73529 | P8: 人脸产品、集成产品 | Q8: 无
B9: 6 | C9: 浪潮软件科技有限公司 | D9: 240.19912 | F9: 人脸产品、集成产品 | G9: 无 | H9: 广州明剑电子科技有限公司 | I9: 515.29203 | K9: 虹膜产品 | L9: 无 | M9: 浪潮软件集团有限公司 | N9: 345.6817 | P9: 人脸产品 | Q9: 无
B10: 7 | C10: 深圳南天东华科技有限公司 | D10: 222.04049 | F10: 指纹、人脸产品 | G10: 无 | H10: 深圳怡化金融设备制造有限公司 | I10: 504.91605 | K10: 指纹、人脸产品 | L10: 无 | M10: 广电运通金融电子股份有限公司 | N10: 286.59512 | P10: 指纹、人脸产品 | Q10: 无
B11: 8 | C11: 山东大学 | D11: 194.07991 | F11: 人脸产品、集成产品、软件类产品 | G11: 无 | H11: 云南南天信息设备有限公司 | I11: 486.74809 | K11: 指纹、人脸产品 | L11: 无 | M11: 恒银金融科技有限公司 | N11: 243.28408 | P11: 指纹、人脸产品 | Q11: 无
B12: 9 | C12: 珠海汇金科技股份有限公司 | D12: 148.63894 | F12: 指纹、人脸产品 | G12: 无 | H12: 浪潮软件集团有限公司 | I12: 468.50397 | K12: 人脸类产品 | L12: 无 | M12: 深圳南天东华科技有限公司 | N12: 238.35461 | P12: 指纹产品 | Q12: 无
B13: 10 | C13: 云南南天信息设备有限公司 | D13: 133.97859 | F13: 指纹、人脸产品 | G13: 无 | H13: 北京创意云智数据技术有限公司 | I13: 456.57423 | K13: 指纹产品 | L13: 无 | M13: 湖南长城信息金融设备有限责任公司 | N13: 221.45062 | P13: 指纹、人脸产品 | Q13: 无
B14: - | C14: 小计 | D14: =SUM(D4:D13) -> 2989.4266 | E14: =SUM(E4:E13) -> 0 | H14: 小计 | I14: =SUM(I4:I13) -> 8589.0345 | M14: 小计 | N14: =SUM(N4:N13) -> 5680.0791
B15: - | C15: 销售收入总金额 | D15: =合并口径财务报表!C3/10000 -> 5228.561 | H15: 销售收入总金额 | I15: =合并口径财务报表!D3/10000 -> 16878.297 | M15: 销售收入总金额 | N15: 10285.86
C17: 我公司北眼科技主要负责生产和研发，北眼智能主要负责销售，合并层面成本金额需要按照北眼科技的成本列示。前十大客户按照订单确收总额列示，因订单数量较多，每个订单产品不同，且相同产品每个月的成本也不尽相同，抵消难度较大，因此这里暂不提供。
B20: 前10名供应商采购额情况表
B21: 序号 | C21: ='收入、毛利率构成表'!C2 -> 2020年1-6月 | H21: ='收入、毛利率构成表'!G2 -> 2019年 | M21: ='收入、毛利率构成表'!K2 -> 2018年
C22: 供货商名称 | D22: 金额（不含税） | E22: 比例 | F22: 采购品类 | G22: 是否关联 | H22: 供货商名称 | I22: 金额（不含税） | J22: 比例 | K22: 采购品类 | L22: 是否关联 | M22: 供货商名称 | N22: 金额（不含税） | O22: 比例 | P22: 采购品类 | Q22: 是否关联
B23: 1 | C23: 贝伦企业股份有限公司 | D23: 388.5417 | E23: 0.24937666 | F23: 传感器 | G23: 否 | H23: IMAGE MATCH DESING INC.（映智科技股份有限公司） | I23: 893.53299 | J23: 0.1851201 | K23: 传感器 | L23: 否 | M23: IMAGE MATCH DESING INC.（映智科技股份有限公司） | N23: 1650.5108 | O23: 0.29060024 | P23: 传感器 | Q23: 否
B24: 2 | C24: IMAGE MATCH DESING INC.（映智科技股份有限公司） | D24: 347.2684 | E24: 0.22288633 | F24: 传感器 | G24: 否 | H24: 贝伦企业股份有限公司 | I24: 779.19961 | J24: 0.16143275 | K24: 传感器 | L24: 否 | M24: 深圳冠伦生物科技有限公司 | N24: 566.18742 | O24: 0.099686839 | P24: 传感器 | Q24: 否
B25: 3 | C25: 深圳市优宝益电子科技有限公司 | D25: 105.67964 | E25: 0.067828078 | F25: 芯片 | G25: 否 | H25: 深圳市迪安杰智能识别科技有限公司 | I25: 367.75487 | J25: 0.076190594 | K25: 传感器 | L25: 否 | M25: 贝伦企业股份有限公司 | N25: 454.6849 | O25: 0.08005494 | P25: 传感器 | Q25: 否
B26: 4 | C26: 广东天波信息技术股份有限公司 | D26: 94.039826 | E26: 0.060357325 | F26: 集成产品 | G26: 否 | H26: 深圳市优吉盛有限公司 | I26: 265.33373 | J26: 0.054971222 | K26: 芯片 | L26: 否 | M26: 深圳市博科供应链管理有限公司 | N26: 348.28095 | O26: 0.061320731 | P26: 传感器 | Q26: 否
B27: 5 | C27: 深圳市鑫科特光电有限公司 | D27: 70.919471 | E27: 0.04551805 | F27: 镜头 | G27: 否 | H27: 深圳市鑫科特光电有限公司 | I27: 252.99189 | J27: 0.052414268 | K27: 镜头 | L27: 否 | M27: 深圳市优吉盛有限公司 | N27: 246.3301 | O27: 0.043370565 | P27: 芯片 | Q27: 否
B28: 6 | C28: 深圳领跑光电有限公司 | D28: 68.476815 | E28: 0.043950287 | F28: 传感器 | G28: 否 | H28: 深圳市博科供应链管理有限公司 | I28: 206.42278 | J28: 0.042766189 | K28: 传感器 | L28: 否 | M28: 杭州晟元数据安全技术股份有限公司 | N28: 186.88933 | O28: 0.032905017 | P28: 芯片 | Q28: 否
B29: 7 | C29: 深圳市迪安杰智能识别科技有限公司 | D29: 62.376335 | E29: 0.040034833 | F29: 传感器 | G29: 否 | H29: 上海睿徕实业有限公司 | I29: 181.48004 | J29: 0.037598611 | K29: 线材 | L29: 否 | M29: 深圳市迪安杰智能识别科技有限公司 | N29: 182.44974 | O29: 0.032123351 | P29: 传感器 | Q29: 否
B30: 8 | C30: 江苏邦融微电子有限公司 | D30: 57.345132 | E30: 0.036805669 | F30: 芯片 | G30: 否 | H30: 深圳市优宝益电子科技有限公司 | I30: 141.05221 | J30: 0.029222868 | K30: 芯片 | L30: 否 | M30: 北京美尔达科技发展有限公司 | N30: 141.07383 | O30: 0.024838425 | P30: 电子料 | Q30: 否
B31: 9 | C31: 上海睿徕实业有限公司 | D31: 47.078941 | E31: 0.030216548 | F31: 线材 | G31: 否 | H31: 深圳市海平面新材料技术有限公司 | I31: 105.09121 | J31: 0.021772552 | K31: 壳体 | L31: 否 | M31: 深圳市富士智能系统有限公司 | N31: 138.30534 | O31: 0.024350985 | P31: 闸机 | Q31: 否
B32: 10 | C32: 湖南博泰供应链管理有限公司 | D32: 39.033014 | E32: 0.025052453 | F32: 传感器 | G32: 否 | H32: 深圳市维德路电子有限公司 | I32: 103.79957 | J32: 0.021504952 | K32: 传感器 | L32: 否 | M32: 深圳市汇利斯通信息技术有限公司 | N32: 130.14646 | O32: 0.022914478 | P32: 人脸识别闸机头 | Q32: 否
B33: - | C33: 小计 | D33: 1280.7593 | E33: 0.82202623 | H33: 小计 | I33: 3296.6589 | J33: 0.68299408 | M33: 小计 | N33: 4044.8588 | O33: 0.71216557
B34: - | C34: 采购去税总金额 | D34: 1558.0516 | E34: - | H34: 采购去税总金额 | I34: 4826.7752 | J34: - | M34: 采购去税总金额 | N34: 5679.6607 | O34: -

Sheet 四大费用明细
B1: 合并层面销售费用明细表
B2: 性质 | C2: ='收入、毛利率构成表'!C2 -> 2020年1-6月 | D2: ='收入、毛利率构成表'!G2 -> 2019年 | E2: ='收入、毛利率构成表'!K2 -> 2018年
B3: 职工薪酬及劳务费 | C3: 678.86082 | D3: 1438.3061 | E3: 1287.0789
B4: 广告费 | C4: 16.392593 | D4: 48.187519 | E4: 169.6506
B5: 展览及物料消耗费 | C5: 4.817766 | D5: 69.145142 | E5: 12.792224
B6: 服务费 | C6: 259.6359 | D6: 583.84898 | E6: 325.28299
B7: 差旅费 | C7: 7.263909 | D7: 225.38768 | E7: 213.20077
B8: 邮费及运费 | C8: 4.241864 | D8: 51.976497 | E8: 55.294012
B9: 租赁及物业费 | C9: 26.855588 | D9: 23.817625 | E9: 2.575166
B10: 业务招待费 | C10: 26.948579 | D10: 194.3003 | E10: 239.63976
B11: 折旧及摊销费 | C11: 29.25689 | D11: 9.143412 | E11: 3.754298
B12: 修理费 | C12: 13.529801 | D12: 0.325712 | E12: 1.730096
B13: 办公费 | C13: 0.632261 | D13: 18.716698 | E13: 40.703983
B14: 水电费 | D14: 1.591446 | E14: 0.086178
B15: 交通运输费 | D15: 14.442368 | E15: 14.755348
B16: 其他 | C16: 0.186792 | D16: 26.705961 | E16: 288.0989
B17: 合计 | C17: =SUM(C3:C16) -> 1068.6228 | D17: =SUM(D3:D16) -> 2705.8955 | E17: =SUM(E3:E16) -> 2654.6432
C18: ='报告（自动生成）'!C6-四大费用明细!C17 -> 0 | D18: ='报告（自动生成）'!D6-四大费用明细!D17 -> 0 | E18: ='报告（自动生成）'!E6-四大费用明细!E17 -> 0
B19: 合并层面管理费用明细表
B20: 性质 | C20: =C2 -> 2020年1-6月 | D20: =D2 -> 2019年 | E20: =E2 -> 2018年
B21: 职工薪酬及劳务费 | C21: 572.2205 | D21: 1297.2308 | E21: 1969.6761
B22: 租赁及物业费 | C22: 103.41 | D22: 419.43946 | E22: 368.08812
B23: 折旧及摊销费 | C23: 55.020895 | D23: 65.546729 | E23: 50.268665
B24: 水电费 | C24: 4.03 | D24: 26.003835 | E24: 51.232799
B25: 服务费 | C25: 217.76896 | D25: 363.2215 | E25: 410.29392
B26: 差旅费 | C26: 12.936287 | D26: 20.613875 | E26: 101.26937
B27: 税费 | D27: 26.366725 | E27: 77.738081
B28: 材料消耗 | C28: 11.554386 | D28: 58.526824 | E28: 17.266084
B29: 业务招待费 | C29: 6.511072 | D29: 33.475205 | E29: 65.332028
B30: 交通费 | C30: 3.763914 | D30: 50.740196 | E30: 43.399996
B31: 办公费 | C31: 43.28 | D31: 54.381536 | E31: 199.3204
B32: 修理费 | C32: 5.21395 | D32: 2.404072 | E32: 32.63048
B33: 运输费 | D33: 6.214244 | E33: 5.293159
B34: 技术服务费 | C34: 38.745106 | D34: 78.291413 | E34: 74.639397
B35: 广告费 | D35: 0 | E35: 12.51274
B36: 存货盘亏 | D36: 0 | E36: 43.390586
B37: 股份支付费用 | D37: 0 | E37: 0
B38: 其他 | C38: 1.42 | D38: 44.188797 | E38: 392.02511
B39: 合计 | C39: =SUM(C21:C38) -> 1075.8751 | D39: =SUM(D21:D38) -> 2546.6452 | E39: =SUM(E21:E38) -> 3914.377
C40: ='报告（自动生成）'!C7-四大费用明细!C39 -> -0.000575 | D40: ='报告（自动生成）'!D7-四大费用明细!D39 -> 0 | E40: ='报告（自动生成）'!E7-四大费用明细!E39 -> 0
...

Sheet 减值准备变动表
B1: 减值准备表
B2: 项目 | C2: 2018年1月1日余额 | D2: 2018年计提 | E2: 2018年转回 | F2: 2018年核销 | G2: 2018年12月31日余额 | H2: 2019年计提 | I2: 2019年转回 | J2: 2019年核销 | K2: 2019年12月31日余额 | L2: 2020年计提 | M2: 2020年转回 | N2: 2020年核销 | O2: 2020年6月30日余额
B3: 应收账款坏账准备 | C3: 319.30054 | D3: 0 | E3: 0 | F3: 0 | G3: 496.8541 | H3: 0 | I3: 0 | J3: 0 | K3: 484.41525 | L3: 0 | M3: 0 | N3: 0 | O3: 347.17143
B4: 其他应收坏账准备 | C4: 445.26507 | D4: 0 | E4: 0 | F4: 0 | G4: 370.56865 | H4: 0 | I4: 0 | J4: 0 | K4: 357.00376 | L4: 0 | M4: 0 | N4: 0 | O4: 384.71202
B5: 存货跌价准备 | O5: 663.78594
B6: 固定资产减值准备
B7: 无形资产减值准备
B8: 商誉减值准备
B9: 短期投资跌价准备
B10: 可供出售金融资产减值准备
B11: 持有至到期投资减值准备
B12: 长期股权投资减值准备
B13: 长期债权投资减值准备
B14: 投资性房地产减值准备
B15: 工程物资减值准备
B16: 在建工程减值准备
B17: 生产性生物资产减值准备
... B20: 合计

Sheet 营业外收支
B1: 合并层面营业外收入明细表
B2: 项目 | C2: ='收入、毛利率构成表'!C2 -> 2020年1-6月 | D2: ='收入、毛利率构成表'!G2 -> 2019年 | E2: ='收入、毛利率构成表'!K2 -> 2018年
B3: 政府补助利得 | C3: 26.020563 | D3: 0.594387 | E3: 0
B4: 盘盈利得 | C4: 0 | D4: 9.031253 | E4: 0
B5: 违约赔偿收入 | C5: 0 | D5: 0 | E5: 11.135684
B6: 其他利得 | C6: 0.350169 | D6: 16.163732 | E6: 0.808539
B7: 合计 | C7: =SUM(C3:C6) -> 26.370732 | D7: =SUM(D3:D6) -> 25.789372 | E7: =SUM(E3:E6) -> 11.944223
C8: =C7='报告（自动生成）'!C19 -> TRUE
B9: 合并层面营业外支出明细表
B10: 项目 | C10: ='收入、毛利率构成表'!C2 -> 2020年1-6月 | D10: ='收入、毛利率构成表'!G2 -> 2019年 | E10: ='收入、毛利率构成表'!K2 -> 2018年
B11: 非流动资产处置损失 | C11: 0.197597 | D11: 0.221301 | E11: 0
B12: 盘亏损失 | C12: 0.29 | D12: 0.049192 | E12: 0
B13: 罚款支出 | C13: 0.08 | D13: 0 | E13: 0.1
B14: 赔偿金、违约金及罚款支出 | C14: 0 | D14: 0.003681 | E14: 41.3361
B15: 其他支出 | C15: 0 | D15: 0.620018 | E15: 2.941286
B16: 合计 | C16: =SUM(C11:C15) -> 0.567597 | D16: =SUM(D11:D15) -> 0.894192 | E16: =SUM(E11:E15) -> 44.377386
C17: =C16='报告（自动生成）'!C20 -> TRUE

Sheet 员工薪酬
B2: 部门 | C2: ='收入、毛利率构成表'!C2 -> 2020年1-6月 | G2: ='收入、毛利率构成表'!G2 -> 2019年 | K2: ='收入、毛利率构成表'!K2 -> 2018年 | O2: 单位：元
C3: 平均人数 | D3: 工资+奖金 | E3: 五险一金 | F3: 平均人工成本 | G3: 平均人数 | H3: 工资+奖金 | I3: 五险一金 | J3: 平均人工成本 | K3: 平均人数 | L3: 工资+奖金 | M3: 五险一金 | N3: 平均人工成本
B4: 总裁办 | C4: 7 | D4: 1709864 | E4: 171500 | F4: 44794.381 | G4: 5 | H4: 3823804 | I4: 715905 | J4: 75661.817 | K4: 7 | L4: 5984376 | M4: 742659 | N4: 80083.75
B5: 研发 | C5: 110 | D5: 10287292 | E5: 1366750 | F5: 17657.639 | G5: 113 | H5: 22189543 | I5: 4219218 | J5: 19475.487 | K5: 141 | L5: 24798166 | M5: 4240845 | N5: 17162.536
B6: 营销市场 | C6: 50 | D6: 5319006 | E6: 752366 | F6: 20237.907 | G6: 60 | H6: 13133777 | I6: 2221494 | J6: 21326.765 | K6: 57 | L6: 9639323 | M6: 1705149 | N6: 16585.485
B7: 运营 | C7: 30 | D7: 1726042 | E7: 241173 | F7: 10928.972 | G7: 25 | H7: 3208663 | I7: 504173 | J7: 12376.12 | K7: 19 | L7: 2584288 | M7: 230333 | N7: 12344.829
B8: 人力行政 | C8: 15 | D8: 744289 | E8: 131495 | F8: 9730.9333 | G8: 15 | H8: 1810276 | I8: 420107 | J8: 12391.017 | K8: 22 | L8: 2422738 | M8: 585280 | N8: 11394.008
B9: 财务 | C9: 12 | D9: 1008828 | E9: 125239 | F9: 15750.931 | G9: 12 | H9: 2013962 | I9: 321324 | J9: 16217.264 | K9: 13 | L9: 1634483 | M9: 261432 | N9: 12153.301
B10: 合计 | C10: =SUM(C4:C9) -> 224 | D10: =SUM(D4:D9) -> 20795321 | E10: =SUM(E4:E9) -> 2788523 | F10: =(D10+E10)/C10/6 -> 17547.503 | G10: =SUM(G4:G9) -> 230 | H10: =SUM(H4:H9) -> 46180025 | I10: =SUM(I4:I9) -> 8402221 | J10: =(H10+I10)/G10/12 -> 19776.176 | K10: =SUM(K4:K9) -> 259 | L10: =SUM(L4:L9) -> 47063374 | M10: =SUM(M4:M9) -> 7765698 | N10: =(L10+M10)/K10/12 -> 17641.272

Sheet 货币资金
A1: 货币资金分类明细 | B1: 44012
A2: 项目 | B2: 金额
A3: 库存现金 | B3: 15.824367
A4: 银行存款 | B4: 607.68571
A5: 其他货币资金
A6: 合计 | B6: =SUM(B3:B5) -> 623.51008
A8: 期末受限制货币资金
A9: 性质 | B9: 金额
A12: 银行存款明细（主要银行账户）
A13: 开户行 | B13: 账号 | C13: 账户性质 | D13: 金额 | E13: 公司名称
A14: 工商银行容城支行8102 | B14: 0413029019100138102 | C14: 一般户 | D14: 0.33399 | E14: 北眼
A15: 农业银行容城县支行8220 | B15: 50509101040018220 | C15: 一般户 | D15: 0.14 | E15: 北眼
A16: 保定容城支行0781 | B16: 545100000012019000781 | C16: 一般户 | D16: 108.73109 | E16: 北眼
A17: 建设银行雄县支行0841 | B17: 13050166840800000841 | C17: 基本户 | D17: 6.271954 | E17: 北眼
A18: 华夏银行容城支行8838 | B18: 13860000000028838 | C18: 一般户 | D18: 5e-05 | E18: 北眼
A19: 招商银行 | B19: 110934151010301 | C19: 一般户 | D19: 11.744117 | E19: 北分
A20: 北京银行股份有限公司中关村支行 | B20: 01090302900120105630205 | C20: 基本存款账户 | D20: 1.209236 | E20: 天诚智能
A21: 招商银行股份有限公司北京西二旗支行 | B21: 110924929910401 | C21: 一般存款账户 | D21: 4.829888 | E21: 天诚智能
A22: 中国工商银行股份有限公司北京中关村支行 | B22: 0200095619200314797 | C22: 一般存款账户 | D22: 1.966656 | E22: 天诚智能
A23: 招商银行股份有限公司深圳宝安支行 | B23: 755942683210111 | C23: 基本户 | D23: 0.284949 | E23: 北京眼神科技有限公司深圳分公司
A24: 招商银行股份有限公司深圳宝安支行 | B24: 755939358010501 | C24: 基本户 | D24: 0.045632 | E24: 北京眼神智能有限公司深圳分公司
A25: 工商银行北京中关村支行 | B25: 0200095619200102864 | C25: 基本户 | D25: 101.89435 | E25: 北眼智能
... A31: 招商银行股份有限公司济南高新支行 | B31: 531904951410902 | C31: 基本户 | D31: 0.030261 | E31: 山东眼神智能科技有限公司
A32: 招行银行深圳科发支行 | B32: 755931641810802 | D32: 13.090954 | E32: 深圳爱酷
A33: 招行银行深圳科发支行 | B33: 755931746110401 | D33: 0.451351 | E33: 深圳眼神
A34: 交通银行股份有限公司郑州商鼎路支行 | B34: 411899991010004624884 | C34: 基本存款账户 | D34: 0.036774 | E34: 河南眼神

Sheet 应收账款明细
B1: 合并层面按客户应收账款明细表（前20大） | K1: =货币资金!B1 -> 44012
B2: 序号 | C2: 客户名称 | D2: 金额 | E2: 比例 | F2: 账龄1年以内金额 | G2: 账龄1-2年金额 | H2: 账龄2-3年金额 | I2: 账龄3-4年金额 | J2: 账龄4-5年金额 | K2: 账龄5年以上金额
B3: 1 | C3: 广州明剑电子科技有限公司 | D3: 516 | E3: =D3/$D$23 -> 0.11460127 | F3: 0.96 | G3: 515.04 | H3: 0 | I3: 0 | J3: 0
B4: 2 | C4: 江苏国光信息产业股份有限公司 | D4: 445.94355 | E4: =D4/$D$23 -> 0.099042046 | F4: 445.94355 | G4: 0 | H4: 0 | I4: 9.3132257e-14 | J4: 0
B5: 3 | C5: 交通银行股份有限公司 | D5: 412.975 | E5: =D5/$D$23 -> 0.091719879 | F5: 412.55 | G5: 0.425 | H5: 0 | I5: 0 | J5: 0
B6: 4 | C6: 深圳市东贵吉科技有限公司 | D6: 395.364 | E6: =D6/$D$23 -> 0.087808556 | F6: 8.955 | G6: 386.409 | H6: 0 | I6: 0 | J6: 0
B7: 5 | C7: 福建升腾资讯有限公司 | D7: 376.4839 | E7: =D7/$D$23 -> 0.083615371 | F7: 376.4839 | G7: 0 | H7: 0 | I7: -9.3132257e-14 | J7: 0
B8: 6 | C8: 山东大学 | D8: 373.8801 | E8: =D8/$D$23 -> 0.083037079 | F8: 219.3071 | G8: 154.573 | H8: 0 | I8: 0 | J8: 0
B9: 7 | C9: 贵州省安顺市公安局西秀分局 | D9: 355.7618 | E9: =D9/$D$23 -> 0.079013086 | F9: 0 | G9: 19.918 | H9: 335.8438 | I9: 0 | J9: 0
B10: 8 | C10: 湖南长城信息金融设备有限责任公司 | D10: 250.41371 | E10: =D10/$D$23 -> 0.055615751 | F10: 250.41371 | G10: 0 | H10: 0 | I10: 0 | J10: 0
B11: 9 | C11: 中国工商银行股份有限公司 | D11: 172 | E11: =D11/$D$23 -> 0.038200422 | F11: 130.24295 | G11: 41.75705 | H11: 0 | I11: 0 | J11: 0
B12: 10 | C12: 浙江省公众信息产业有限公司 | D12: 171.73725 | E12: =D12/$D$23 -> 0.038142066 | F12: 171.73725 | G12: 0 | H12: 0 | I12: 0 | J12: 0
B13: 11 | C13: 浪潮软件科技有限公司 | D13: 157.5 | E13: =D13/$D$23 -> 0.034980037 | F13: 157.5 | G13: 0 | H13: 0 | I13: 0 | J13: 0
B14: 12 | C14: 云南南天信息设备有限公司 | D14: 145.7254 | E14: =D14/$D$23 -> 0.032364952 | F14: 145.7254 | G14: 0 | H14: 0 | I14: 0 | J14: 0
... B22: 20 | C22: 广西北部湾银行股份有限公司 | D22: 71.92 | E22: =D22/$D$23 -> 0.015973107 | F22: 57.6 | G22: 14.32 | H22: 0 | I22: 0 | J22: 0
B23: - | C23: 小计 | D23: =SUM(D3:D22) -> 4502.5681 | E23: =SUM(E3:E22) -> 1 | F23: =SUM(F3:F22) -> 2830.72 | G23: =SUM(G3:G22) -> 1336.0042 | H23: =SUM(H3:H22) -> 335.8438
B25: 应收账款账龄表
C26: 金额 | D26: 计提坏账 | E26: 净额
B27: 1年内 | C27: 3270.6808 | E27: =C27-D27 -> 3270.6808
B28: 1-2年 | C28: 1749.0973 | E28: =C28-D28 -> 1749.0973
B29: 2-3年 | C29: 1229.0312 | E29: =C29-D29 -> 1229.0312
B30: 3-4年 | C30: 91.023489 | E30: =C30-D30 -> 91.023489
B31: 4-5年 | E31: =C31-D31 -> 0
B32: 5年以上 | E32: =C32-D32 -> 0
B33: 合计 | C33: =SUM(C27:C32) -> 6339.8327 | D33: 347.17143 | E33: =SUM(E27:E32)-D33 -> 5992.6613
B35: 应收账款按性质明细
B36: 性质 | C36: 金额
B43: 合计 | C43: =SUM(C37:C42) -> 0

Sheet 预付账款明细
B1: 预付账款按客户明细（前20大） | D1: =应收账款明细!$K$1 -> 44012
B2: 供应商名称 | C2: 金额 | D2: 一年以内 | E2: 1-2年 | F2: 2-3年 | G2: 3年以上
B3: 深圳市吉控科技有限公司 | C3: 132.37741 | D3: 132.37741 | E3: 0 | F3: 0 | G3: 0
B4: 中欧国际工商学院 | C4: 42.5 | D4: 42.5 | E4: 0 | F4: 0 | G4: 0
B5: 深圳领跑光电有限公司 | C5: 40.9488 | D5: 40.9488 | E5: 0 | F5: 0 | G5: 0
B6: 深圳市林慧通科技有限公司 | C6: 33.50672 | D6: 33.50672 | E6: 0 | F6: 0 | G6: 0
B7: 黄宝晗 | C7: 24.4105 | D7: 0 | E7: 0 | F7: 0 | G7: 24.4105
B8: 上海瑜萱信息科技工作室 | C8: 18.72 | D8: 18.72 | E8: 0 | F8: 0 | G8: 0
B9: 河南智慧岛投资有限公司 | C9: 14.29778 | D9: 14.29778 | E9: 0 | F9: 0 | G9: 0
B10: 陈荻玲 | C10: 10.66 | D10: 9.18 | E10: 0 | F10: 0 | G10: 1.48
B11: 北京亿欧网盟科技有限公司 | C11: 10 | D11: 0 | E11: 10 | F11: 0 | G11: 0
B12: 北京众和天下管理咨询有限公司 | C12: 8.768102 | D12: 8.768102 | E12: 0 | F12: 0 | G12: 0
B13: 深圳市迪安杰智能识别科技有限公司 | C13: 8.265111 | D13: 8.265111 | E13: 0 | F13: 0 | G13: 1.4551915e-15
B14: 天津诚美智新企业管理咨询有限公司 | C14: 6.3 | D14: 6.3 | E14: 0 | F14: 0 | G14: 0
... B17: 北京多氪信息科技有限公司 | C17: 5 | D17: 5 | E17: 0 | F17: 0 | G17: 0
B23: 小计 | C23: =SUM(C2:C22) -> 367.32423 | D23: =SUM(D2:D22) -> 331.43373 | E23: =SUM(E2:E22) -> 10 | F23: =SUM(F2:F22) -> 0 | G23: =SUM(G2:G22) -> 25.8905
B26: 预付账款按性质明细
B27: 性质 | C27: 金额
B28: 预付货款 | C28: 350.95036
B29: 预付房租 | C29: =C10+C7 -> 35.0705
B30: 预付培训费 | C30: =C4 -> 42.5
B34: 合计 | C34: =SUM(C28:C33) -> 428.52086

Sheet 其他应收款
B1: 其他应收款按客户明细（前10大） | E1: =应收账款明细!$K$1 -> 44012
B2: 客户名称 | C2: 金额 | D2: 账龄 | E2: 性质
B3: 任丽萍 | C3: 79.434417 | D3: 3年以上
B4: 王雪娇 | C4: 64.481036 | D4: 2-3年
B5: 王海建 | C5: 60 | D5: 1年以内
B6: 肖坤 | C6: 39.04811 | D6: 3年以上
B7: 常立娜 | C7: 37 | D7: 2-3年
B8: 潘驭骐 | C8: 186.8878 | D8: 3年以上
B9: 黄宏建 | C9: 110.466 | D9: 3年以上
B10: 王希佳 | C10: 70.782108 | D10: 2-3年
B11: 郝欣欣 | C11: 51.6809 | D11: 2-3年
B12: 王厚金 | C12: 45.452978 | D12: 2-3年
B13: 合计 | C13: =SUM(C3:C12) -> 745.23335
B16: 其他应收款按性质明细
B17: 性质 | C17: 金额
B24: 合计 | C24: =SUM(C18:C23) -> 0

Sheet 存货分类
B1: 存货分类明细 | E1: =[1]应收账款明细!$K$1 -> 2020年6月30日
B2: 项目 | C2: 金额 | D2: 跌价准备 | E2: 净值
B3: 原材料 | C3: 613.05921 | D3: 220.48474 | E3: =C3-D3 -> 392.57448
B4: 在产品 | C4: 63.100324 | D4: 0 | E4: =C4-D4 -> 63.100324
B5: 库存商品 | C5: 1697.2167 | D5: 443.30121 | E5: =C5-D5 -> 1253.9155
B6: 自制半成品 | C6: 0 | D6: 0 | E6: =C6-D6 -> 0
B7: 备品备件 | C7: 0 | D7: 0 | E7: =C7-D7 -> 0
B8: 在途商品 | C8: 40.08017 | D8: 0 | E8: =C8-D8 -> 40.08017
B9: 发出商品 | C9: 1.221121 | D9: 0 | E9: =C9-D9 -> 1.221121
B10: 委托加工物资 | C10: 19.035779 | D10: 0 | E10: =C10-D10 -> 19.035779
B11: 资本化支出 | C11: 0 | D11: 0 | E11: =C11-D11 -> 0
B12: 生产成本 | C12: 96.263073 | D12: 0 | E12: =C12-D12 -> 96.263073
B13: 劳务成本 | C13: 249.47133 | D13: 0 | E13: =C13-D13 -> 249.47133
B14: 合计 | C14: =SUM(C3:C13) -> 2779.4477 | D14: =SUM(D3:D13) -> 663.78594 | E14: =SUM(E3:E13) -> 2115.6617
E15: ='报告（自动生成）'!C58-存货分类!E14 -> 0.003

Sheet 其他流动资产
B1: 其他流动资产明细 | F1: =应收账款明细!$K$1 -> 44012
B2: 项目 | C2: 金额 | D2: 比例 | E2: 账龄 | F2: 性质
B3: 应交税费-增值税-未交增值税(进项留底） | C3: 26.003522
B13: 合计 | C13: =SUM(C3:C12) -> 26.003522
C14: ='报告（自动生成）'!C61-其他流动资产!C13 -> 0

Sheet 可供出售金融资产
B1: 可供出售金融资产 | E1: =应收账款明细!$K$1 -> 44012
B2: 投资对象 | C2: 金额 | D2: 投资时间 | E2: 性质
B3: 无
B13: 合计 | C13: =SUM(C3:C12) -> 0

Sheet 长期股权投资
B1: 长期股权投资 | F1: =应收账款明细!$K$1 -> 44012
B2: 投资对象 | C2: 金额 | D2: 投资时间 | E2: 占股比例 | F2: 性质
B3: 无
B13: 合计 | C13: =SUM(C3:C12) -> 0

Sheet 商誉
B1: 商誉明细 | F1: =应收账款明细!$K$1 -> 44012
B2: 项目 | C2: 原值 | D2: 跌价准备 | E2: 净值 | F2: 性质
B3: 2016年9月收购天诚智能支付6.6万，账面净资产-30.58万。 | C3: =6.6+30.58 -> 37.18
B13: 合计 | C13: =SUM(C3:C12) -> 37.18

Sheet 固定资产构成表
B1: 固定资产明细表 | F1: 44012
B2: 类型 | C2: 原值 | D2: 累计折旧 | E2: 减值 | F2: 净值
B3: 电子设备 | C3: 636.81643 | D3: 400.72705 | E3: 0 | F3: 236.08938
B4: 办公家具 | C4: 59.62388 | D4: 28.01382 | E4: 0 | F4: 31.61006
B5: 房屋建筑 | C5: 166.34947 | D5: 73.775994 | E5: 0 | F5: 92.573472
B6: 机器设备 | C6: 35.756698 | D6: 3.687763 | E6: 0 | F6: 32.068935
B7: 运输工具 | C7: 198.32132 | D7: 160.2995 | E7: 0 | F7: 38.021818
B8: 合计 | C8: =SUM(C3:C7) -> 1096.8678 | D8: =SUM(D3:D7) -> 666.50412 | E8: =SUM(E3:E7) -> 0 | F8: =C8-D8-E8 -> 430.36367
F9: ='报告（自动生成）'!C68-固定资产构成表!F8 -> 0

Sheet 在建工程
B1: 在建工程明细表 | F1: =应收账款明细!$K$1 -> 44012
B2: 项目 | C2: 期初余额 | D2: 新增金额 | E2: 转固金额 | F2: 期末余额
B3: 无
B8: 合计 | C8: =SUM(C3:C7) -> 0 | D8: =SUM(D3:D7) -> 0 | E8: =SUM(E3:E7) -> 0 | F8: =SUM(F3:F7) -> 0

Sheet 无形资产构成
B1: 无形资产构成 | F1: =应收账款明细!$K$1 -> 44012
B2: 项目 | C2: 取得方式 | D2: 原始金额 | E2: 累计摊销 | F2: 净值
B3: 虹膜识别知识产权 | C3: 投资者投入 | D3: 924.89 | E3: 924.89 | F3: 0
B4: 虹膜锁（技术服务） | C4: 自研 | D4: 488.61693 | E4: 24.430848 | F4: 464.18608
F5: =D5-E5 -> 0
F6: =D6-E6 -> 0
B7: 合计 | D7: =SUM(D3:D6) -> 1413.5069 | E7: =SUM(E3:E6) -> 949.32085 | F7: =SUM(F3:F6) -> 464.18608
F8: ='报告（自动生成）'!C72-F7 -> 0

Sheet 长期待摊费用
B1: 长期待摊费用构成 | E1: =应收账款明细!$K$1 -> 44012
B2: 项目 | C2: 原始金额 | D2: 累计摊销 | E2: 净值
B3: 无 | E3: =C3-D3 -> 0
E4: =C4-D4 -> 0
E5: =C5-D5 -> 0
E6: =C6-D6 -> 0
B7: 合计 | C7: =SUM(C3:C6) -> 0 | D7: =SUM(D3:D6) -> 0 | E7: =SUM(E3:E6) -> 0
E8: ='报告（自动生成）'!D75-E7 -> 0

Sheet 其他非流动资产
B1: 其他非流动资产明细 | F1: =应收账款明细!$K$1 -> 44012
B2: 项目 | C2: 金额 | D2: 比例 | E2: 账龄 | F2: 性质
B3: 无
B13: 合计 | C13: =SUM(C3:C12) -> 0

Sheet 长短期借款
B1: 短期借款明细 | F1: =应收账款明细!$K$1 -> 44012
B2: 贷款银行 | C2: 贷款金额 | D2: 利率 | E2: 性质 | F2: 起止日期 | G2: 起 | H2: 止
B3: 工商银行 | C3: 400 | D3: 0.0385 | E3: 房产 | G3: 43973 | H3: 44245
B4: 工商银行 | C4: 400 | D4: 0.0385 | E4: 房产 | G4: 43973 | H4: 44273
B5: 工商银行 | C5: 400 | D5: 0.0435 | E5: 房产 | G5: 43658 | H5: 44023
B6: 工商银行 | C6: 300 | D6: 0.0435 | E6: 房产 | G6: 43678 | H6: 44043
B7: 工商银行 | C7: 500 | D7: 0.0435 | E7: 房产二抵 | G7: 43782 | H7: 44147
B8: 工商银行 | C8: 300 | D8: 0.0435 | E8: 房产 | G8: 43731 | H8: 44032
B9: 工商银行 | C9: 600 | D9: 0.0435 | E9: 房产 | G9: 43731 | H9: 44096
B10: 北京银行 | C10: 499 | D10: 0.0522 | E10: 信用贷款，质押1个专利 | G10: 43797 | H10: 44162
B11: 广发银行 | C11: 500 | D11: 0.045 | E11: 房产二抵 | G11: 43923 | H11: 44265
B12: 广发银行 | C12: 100 | D12: 0.045 | E12: 信用贷款 | G12: 43929 | H12: 44265
B13: 邮储银行 | C13: 200 | D13: 0.05655 | E13: 信用贷款，质押13个专利 | G13: 43833 | H13: 44198
B14: 雄安交行 | C14: 300 | D14: 0.0435 | E14: 信用贷款 | G14: 44012 | H14: 44376
B16: 合计 | C16: =SUM(C3:C15) -> 4499
C17: ='报告（自动生成）'!C80-C16 -> 0
B19: 长期借款明细 | F19: =应收账款明细!$K$1 -> 44012
B20: 贷款银行 | C20: 贷款金额 | D20: 利率 | E20: 性质 | F20: 起止日期 | G20: 起 | H20: 止
B21: 深圳农商行 | C21: 194 | D21: 0.06 | E21: 信用贷款 | G21: 43922 | H21: 45012
B23: 合计 | C23: =SUM(C21:C22) -> 194
C24: ='报告（自动生成）'!C93-C23 -> 0

Sheet 应付账款
B1: 前10大应付账款明细表 | E1: =应收账款明细!$K$1 -> 44012
B2: 序号 | C2: 供应商名称 | D2: 金额 | E2: 账龄
B3: 1 | C3: IMAGE MATCH DESING INC.（映智科技股份有限公司） | D3: 45.451884 | E3: 2年以内
B4: 2 | C4: 深圳市汇利斯通信息技术有限公司 | D4: 42.928559 | E4: 3年以内
B5: 3 | C5: 贵州创智嘉科技有限公司 | D5: 52.4 | E5: 2年以内
B6: 4 | C6: 周峰 | D6: 43 | E6: 1年以内
B7: 5 | C7: IMAGE MATCH DESING INC.（映智科技股份有限公司） | D7: 398.3764 | E7: 2年以内
B8: 6 | C8: 北京市商汤科技开发有限公司 | D8: 35 | E8: 3年以上
B9: 7 | C9: 贝伦企业股份有限公司 | D9: 441.60174 | E9: 2年以内
B10: 8 | C10: 力恒丰业科技（深圳）有限公司 | D10: 41.521878 | E10: 2年以内
B11: 9 | C11: 深圳市海平面新材料技术有限公司 | D11: 40.294596 | E11: 2年以内
B12: 10 | C12: 深圳市聚芯影像有限公司 | D12: 42.452469 | E12: 2年以内
B13: 合计 | D13: =SUM(D3:D12) -> 1183.0275
B15: 应付账款账龄表
C16: 金额
B17: 1年内 | C17: 1038.9269
B18: 1-2年 | C18: 520.58079
B19: 2-3年 | C19: 87.861466
B20: 3年以上 | C20: 36.588974
B21: 合计 | C21: =SUM(C17:C20) -> 1683.9581
B23: 应付账款按性质明细
B24: 性质 | C24: 金额
B31: 合计 | C31: =SUM(C25:C30) -> 0

Sheet 预收账款
B1: 预收账款明细 | C1: =应收账款明细!$K$1 -> 44012
B2: 客户名称 | C2: 金额
B3: APPLIED—DATA—LOGIX | C3: 4.2e-05
B4: LITTLEMORE—INNOVATION—LABS—PTE | C4: 3.447027
B5: 个人 | C5: 0.5798
B6: 惠州市合众惠创科技有限公司 | C6: 0.044
B7: 山东信久石化有限公司 | C7: 0.3699
B8: 深圳市伟合佳电子科技有限公司 | C8: 0.3
B9: 深圳真金瑷科技有限公司 | C9: 0.175
B10: 北京易捷联创科技有限公司 | C10: 6.0688
B11: 广州阿成科技有限公司 | C11: 0.045
B12: 敖翔 | C12: 0.35
B13: 深圳丽泽智能科技有限公司 | C13: 0.47
B14: 深圳市思航信息科技有限公司 | C14: 0.04
... B278: 中国邮政集团有限公司阳泉市分公司 | C278: 0.006
B279: 小计 | C279: =SUM(C3:C278) -> 356.24055
B282: 预收账款按性质明细
B283: 性质 | C283: 金额
B284: 预收货款 | C284: 356.24055
B290: 合计 | C290: =SUM(C284:C289) -> 356.24055

Sheet 其他应付
B1: 其他应付款明细 | E1: =应收账款明细!$K$1 -> 44012
B2: 项目 | C2: 金额 | D2: 比例 | E2: 性质
B3: 艾尔发企业管理咨询（上海）有限公司 | C3: 0.06
B4: 安徽动高科技有限公司 | C4: 0.12
B5: 北京成世科技有限责任公司 | C5: 0.201776
B6: 北京德润会计师事务所 | C6: 0.5
B7: 北京德润税务师事务所有限公司 | C7: 0.5
B8: 北京恩赫律师事务所 | C8: 3.09
B9: 北京宏德信智源泉技术公司 | C9: 0.2
B10: 北京华宇软件股份有限公司 | C10: 0.06
B11: 北京进源清洁服务有限公司 | C11: 0.04
B12: 北京精准博创电子科技有限公司 | C12: 2.14098
B13: 北京聚宝网络科技有限公司 | C13: 0.1
B14: 北京康信知识产权代理有限责任公司 | C14: 27.64206
... B111: 珠海市金鼎新华盛机械厂 | C111: 0.15
B112: 合计 | C112: =SUM(C3:C111) -> 3327.9288

Sheet 其他流动负债
B1: 其他流动负债明细 | E1: =应收账款明细!$K$1 -> 44012
B2: 项目 | C2: 金额 | D2: 比例 | E2: 性质
B3: 黄宏建股权转让个税 | C3: 587.5
B13: 合计 | C13: =SUM(C3:C12) -> 587.5

Sheet 其他非流动负债
B1: 其他非流动负债明细 | E1: =应收账款明细!$K$1 -> 44012
B2: 项目 | C2: 金额 | D2: 比例 | E2: 性质
B3: 无
B13: 合计 | C13: =SUM(C3:C12) -> 0
